<?xml version="1.0" ?>
<robot
  xmlns:xacro="http://www.ros.org/wiki/xacro">


  <gazebo>
      <plugin name="ros_control" filename="libros_control_gazebo_plugin.so">
        <ns>denso/ros_control</ns>
        <robotSimType>ros_control_gazebo_tests/MTMSim</robotSimType>
        <controlPeriod>0.001</controlPeriod>
      </plugin>
    </gazebo>

  <link name="base">
    <visual>
      <origin xyz="0 0 0.098" rpy="0 0 0" />
      <geometry >
	<mesh filename="package://denso_arm/meshes/" />
      </geometry>
      <material name="denso_light_gray" />
    </visual>
     <inertial>
        <mass value="9"/>
        <inertia ixx="9.0" ixy="0.0" ixz="0.0" iyy="9.0" iyz="0.0" izz="9.0"/>
      </inertial> 
  </link>

  <link name="link_1">
    <visual>
      <origin xyz="0 0 0.06" rpy="0 0 0" />
      <geometry >
	<mesh filename="package://denso_arm/meshes" />
      </geometry>
      <material name="denso_light_gray" />
     </visual>
     <inertial>
        <mass value="8"/>
        <inertia ixx="8.0" ixy="0.0" ixz="0.0" iyy="8.0" iyz="0.0" izz="8.0"/>
      </inertial> 
  </link>

  <joint name="denso_J0" type="revolute">
    <parent link="base"/>
    <child link="link_1"/>
    <origin xyz="0 0 0.198" rpy="0 0 1.57" />
    <axis xyz="0 0 1" />
    <limit lower="-2.967" upper="2.967" effort="10"
	   velocity="1.0" />
    <joint_properties damping="0.0" friction="0.0"/>
  </joint>

  <link name="link_2">
    <visual>
      <origin xyz="0 0 0.225" rpy="0 0 0" />
      <geometry >
	<mesh filename="package://denso_arm/meshes" />
      </geometry>
      <material name="denso_med_gray" />
    </visual>
        <inertial>
        <mass value="7"/>
        <inertia ixx="7.0" ixy="0.0" ixz="0.0" iyy="7.0" iyz="0.0" izz="7.0"/>
      </inertial> 
  </link>

  <joint name="denso_J1" type="revolute">
    <parent link="link_1"/>
    <child link="link_2"/>
    <origin xyz="0 0 0.190" rpy="0 0 0" />
    <axis xyz="1 0 0" />
    <limit lower="-1.745" upper="2.356" effort="10"
	   velocity="1.0" />
    <joint_properties damping="0.0" friction="0.0"/>
  </joint>

  <link name="link_3">
    <visual>
      <origin xyz="0 0 0.1425" rpy="0 0 0" />
      <geometry >
	<mesh filename="package://denso_arm/meshes" />
      </geometry>
      <material name="denso_dark_gray" />
    </visual>
    <inertial>
        <mass value="6"/>
        <inertia ixx="6.0" ixy="0.0" ixz="0.0" iyy="6.0" iyz="0.0" izz="6.0"/>
      </inertial> 
  </link>

  <joint name="denso_J2" type="revolute">
    <parent link="link_2"/>
    <child link="link_3"/>
    <origin xyz="0 0 0.450" rpy="0 0 0" />
    <axis xyz="1 0 0" />
    <limit lower="-2.094" upper="2.670" effort="10"
	   velocity="1.0" />
    <joint_properties damping="0.0" friction="0.0"/>
  </joint>

  <link name="link_4">
    <visual>
      <origin xyz="0 0 0.0675" rpy="0 0 0" />
      <geometry >
	<mesh filename="package://denso_arm/meshes" />
      </geometry>
      <material name="denso_light_gray" />
    </visual>
       <inertial>
        <mass value="5"/>
        <inertia ixx="5.0" ixy="0.0" ixz="0.0" iyy="5.0" iyz="0.0" izz="5.0"/>
      </inertial> 
  </link>

  <joint name="denso_J3" type="revolute">
    <parent link="link_3"/>
    <child link="link_4"/>
    <origin xyz="0 0 0.285" rpy="0 0 0" />
    <axis xyz="0 0 1" />
    <limit lower="-4.712" upper="4.712" effort="10"
	   velocity="1.0" />
    <joint_properties damping="0.0" friction="0.0"/> 
 </joint>

  <link name="link_5">
    <visual>
      <origin xyz="0 0 0.045" rpy="0 0 0" />
      <geometry >
	<mesh filename="package://denso_arm/meshes" />
      </geometry>
      <material name="denso_light_gray" />
    </visual>
       <inertial>
        <mass value="4"/>
        <inertia ixx="4.0" ixy="0.0" ixz="0.0" iyy="4.0" iyz="0.0" izz="4.0"/>
      </inertial> 
  </link>

  <joint name="denso_J4" type="revolute">
    <parent link="link_4"/>
    <child link="link_5"/>
    <origin xyz="0 0 0.135" rpy="0 0 0" />
    <axis xyz="1 0 0" />
    <limit lower="-2.094" upper="2.094" effort="10"
	   velocity="1.0" />
    <joint_properties damping="0.0" friction="0.0"/>
  </joint>

  <link name="link_6">
    <visual>
      <origin xyz="0 0 0.0005" rpy="0 0 0" />
      <geometry >
	<mesh filename="package://denso_arm/meshes" />
      </geometry>
      <material name="denso_light_gray" />
    </visual>
       <inertial>
        <mass value="2"/>
        <inertia ixx="2.0" ixy="0.0" ixz="0.0" iyy="2.0" iyz="0.0" izz="2.0"/>
      </inertial> 
  </link>

  <joint name="denso_J5" type="revolute">
    <parent link="link_5"/>
    <child link="link_6"/>
    <origin xyz="0 0 0.090" rpy="0 0 0" />
    <axis xyz="0 0 1" />
    <limit lower="-6.283" upper="6.283" effort="10"
	   velocity="1.0" />
    <joint_properties damping="0.0" friction="0.0"/>
  </joint>
</robot>
